<?xml version="1.0" ?>
<robot name="2dof" >

<link name="tool0"/>

<link name="base_link">
  <visual>
    <origin xyz="0 0 1.15" rpy="0 0 0"/>
    <geometry>
      <box size="0.3 0.3 2.3"/>
    </geometry>
  </visual>
</link>

<link name="link_1">
  <visual>
    <origin xyz="0 0 1" rpy="0 0 0"/>
    <geometry>
      <box size="0.2 0.2 2"/>
    </geometry>
  </visual>
</link>

<link name="link_2">
  <visual>
    <origin xyz="0 0 0.65" rpy="0 0 0"/>
    <geometry>
      <box size="0.1 0.1 1.3"/>
    </geometry>
  </visual>
</link>

<link name="link_3">
  <visual>
    <origin xyz="0 0 0.05" rpy="0 0 0"/>
    <geometry>
      <box size="0.1 0.1 0.1"/>
    </geometry>
  </visual>
</link>

  <joint name="joint_1" type="revolute">
    <parent link="base_link" />
    <child link="link_1" />
    <limit effort="30" velocity="1.0" lower="-3.14" upper="3.14" />
    <origin xyz="0 0 2.3" rpy="0 1.57 0" />
    <axis xyz="1 0 0" />
  </joint>
	
  <joint name="joint_2" type="revolute">
    <parent link="link_1" />
    <child link="link_2" />
    <limit effort="30" velocity="1.0" lower="-3.14" upper="3.14" />
    <origin xyz="0 0 2" rpy="0 0 0" />
    <axis xyz="0 1 0" />
  </joint>

 <joint name="joint_3" type="revolute">
    <parent link="link_2" />
    <child link="link_3" />
    <limit effort="30" velocity="1.0" lower="-3.14" upper="3.14" />
    <origin xyz="0 0 1.3" rpy="0 0 0" />
    <axis xyz="0 1 0" />
  </joint>

<joint name="joint_3-tool0" type="revolute">
    <parent link="link_3" />
    <child link="tool0" />
    <limit effort="30" velocity="1.0" lower="-6.28318" upper="6.28318" />
    <origin xyz="0 0 0" rpy="0 0 0" />
    <axis xyz="0 0 1" />
  </joint>

</robot>

